{
  "error": "An exception occurred during backtesting: None",
  "traceback": [
    "Traceback (most recent call last):\n  File \"/backend-api/routers/manage_backtesting.py\", line 89, in run_backtesting\n    backtesting_results = await backtesting_engine.run_backtesting(\n                          ^^^^^^^^^^^^^^^^^^^^^^^^^^^^^^^^^^^^^^^^^\n  File \"/opt/conda/envs/backend-api/lib/python3.12/site-packages/hummingbot/strategy_v2/backtesting/backtesting_engine_base.py\", line 91, in run_backtesting\n    await self.backtesting_data_provider.initialize_trading_rules(controller_config.connector_name)\n  File \"/opt/conda/envs/backend-api/lib/python3.12/site-packages/hummingbot/strategy_v2/backtesting/backtesting_data_provider.py\", line 75, in initialize_trading_rules\n    connector = self.connectors.get(connector_name)\n                ^^^^^^^^^^^^^^^^^^^^^^^^^^^^^^^^^^^\n  File \"/opt/conda/envs/backend-api/lib/python3.12/site-packages/hummingbot/core/data_type/common.py\", line 118, in get\n    return self.__missing__(key)\n           ^^^^^^^^^^^^^^^^^^^^^\n  File \"/opt/conda/envs/backend-api/lib/python3.12/site-packages/hummingbot/core/data_type/common.py\", line 111, in __missing__\n    self[key] = self.default_value_factory(key)\n                ^^^^^^^^^^^^^^^^^^^^^^^^^^^^^^^\n  File \"/opt/conda/envs/backend-api/lib/python3.12/site-packages/hummingbot/strategy_v2/backtesting/backtesting_data_provider.py\", line 39, in <lambda>\n    self.conn_settings[name].type in self.CONNECTOR_TYPES and\n    ~~~~~~~~~~~~~~~~~~^^^^^^\nKeyError: None\n"
  ]
}