{
  "error": "An exception occurred during backtesting: Error executing request GET https://fapi.binance.com/fapi/v1/exchangeInfo. HTTP status is 451. Error: {\n  \"code\": 0,\n  \"msg\": \"Service unavailable from a restricted location according to 'b. Eligibility' in https://www.binance.com/en/terms. Please contact customer service if you believe you received this message in error.\"\n}",
  "traceback": [
    "Traceback (most recent call last):\n  File \"/backend-api/routers/manage_backtesting.py\", line 65, in run_backtesting\n    backtesting_results = await backtesting_engine.run_backtesting(\n                          ^^^^^^^^^^^^^^^^^^^^^^^^^^^^^^^^^^^^^^^^^\n  File \"/opt/conda/envs/backend-api/lib/python3.12/site-packages/hummingbot/strategy_v2/backtesting/backtesting_engine_base.py\", line 91, in run_backtesting\n    await self.backtesting_data_provider.initialize_trading_rules(controller_config.connector_name)\n  File \"/opt/conda/envs/backend-api/lib/python3.12/site-packages/hummingbot/strategy_v2/backtesting/backtesting_data_provider.py\", line 76, in initialize_trading_rules\n    await connector._update_trading_rules()\n  File \"/opt/conda/envs/backend-api/lib/python3.12/site-packages/hummingbot/connector/exchange_py_base.py\", line 854, in _update_trading_rules\n    exchange_info = await self._make_trading_rules_request()\n                    ^^^^^^^^^^^^^^^^^^^^^^^^^^^^^^^^^^^^^^^^\n  File \"/opt/conda/envs/backend-api/lib/python3.12/site-packages/hummingbot/connector/exchange_py_base.py\", line 1082, in _make_trading_rules_request\n    exchange_info = await self._api_get(path_url=self.trading_rules_request_path)\n                    ^^^^^^^^^^^^^^^^^^^^^^^^^^^^^^^^^^^^^^^^^^^^^^^^^^^^^^^^^^^^^\n  File \"/opt/conda/envs/backend-api/lib/python3.12/site-packages/hummingbot/connector/exchange_py_base.py\", line 863, in _api_get\n    return await self._api_request(*args, **kwargs)\n           ^^^^^^^^^^^^^^^^^^^^^^^^^^^^^^^^^^^^^^^^\n  File \"/opt/conda/envs/backend-api/lib/python3.12/site-packages/hummingbot/connector/exchange_py_base.py\", line 906, in _api_request\n    request_result = await rest_assistant.execute_request(\n                     ^^^^^^^^^^^^^^^^^^^^^^^^^^^^^^^^^^^^^\n  File \"/opt/conda/envs/backend-api/lib/python3.12/site-packages/hummingbot/core/web_assistant/rest_assistant.py\", line 47, in execute_request\n    response = await self.execute_request_and_get_response(\n               ^^^^^^^^^^^^^^^^^^^^^^^^^^^^^^^^^^^^^^^^^^^^\n  File \"/opt/conda/envs/backend-api/lib/python3.12/site-packages/hummingbot/core/web_assistant/rest_assistant.py\", line 100, in execute_request_and_get_response\n    raise IOError(f\"Error executing request {method.name} {url}. HTTP status is {response.status}. \"\nOSError: Error executing request GET https://fapi.binance.com/fapi/v1/exchangeInfo. HTTP status is 451. Error: {\n  \"code\": 0,\n  \"msg\": \"Service unavailable from a restricted location according to 'b. Eligibility' in https://www.binance.com/en/terms. Please contact customer service if you believe you received this message in error.\"\n}\n"
  ]
}