{
  "error": "An exception occurred during backtesting: 2 validation errors for DManV3ControllerConfig\ndynamic_order_spread\n  Input should be a valid boolean [type=bool_type, input_value=None, input_type=NoneType]\n    For further information visit https://errors.pydantic.dev/2.11/v/bool_type\ndynamic_target\n  Input should be a valid boolean [type=bool_type, input_value=None, input_type=NoneType]\n    For further information visit https://errors.pydantic.dev/2.11/v/bool_type",
  "traceback": [
    "Traceback (most recent call last):\n  File \"/backend-api/routers/manage_backtesting.py\", line 60, in run_backtesting\n    controller_config = backtesting_engine.get_controller_config_instance_from_dict(\n                        ^^^^^^^^^^^^^^^^^^^^^^^^^^^^^^^^^^^^^^^^^^^^^^^^^^^^^^^^^^^^\n  File \"/opt/conda/envs/backend-api/lib/python3.12/site-packages/hummingbot/strategy_v2/backtesting/backtesting_engine_base.py\", line 80, in get_controller_config_instance_from_dict\n    return config_class(**config_data)\n           ^^^^^^^^^^^^^^^^^^^^^^^^^^^\n  File \"/opt/conda/envs/backend-api/lib/python3.12/site-packages/pydantic/main.py\", line 253, in __init__\n    validated_self = self.__pydantic_validator__.validate_python(data, self_instance=self)\n                     ^^^^^^^^^^^^^^^^^^^^^^^^^^^^^^^^^^^^^^^^^^^^^^^^^^^^^^^^^^^^^^^^^^^^^\npydantic_core._pydantic_core.ValidationError: 2 validation errors for DManV3ControllerConfig\ndynamic_order_spread\n  Input should be a valid boolean [type=bool_type, input_value=None, input_type=NoneType]\n    For further information visit https://errors.pydantic.dev/2.11/v/bool_type\ndynamic_target\n  Input should be a valid boolean [type=bool_type, input_value=None, input_type=NoneType]\n    For further information visit https://errors.pydantic.dev/2.11/v/bool_type\n"
  ]
}