{
  "error": "An exception occurred during backtesting: 'XEMMMultipleLevelsConfig' object has no attribute 'trading_pair'",
  "traceback": [
    "Traceback (most recent call last):\n  File \"/backend-api/routers/manage_backtesting.py\", line 65, in run_backtesting\n    backtesting_results = await backtesting_engine.run_backtesting(\n                          ^^^^^^^^^^^^^^^^^^^^^^^^^^^^^^^^^^^^^^^^^\n  File \"/opt/conda/envs/backend-api/lib/python3.12/site-packages/hummingbot/strategy_v2/backtesting/backtesting_engine_base.py\", line 97, in run_backtesting\n    executors_info = await self.simulate_execution(trade_cost=trade_cost)\n                     ^^^^^^^^^^^^^^^^^^^^^^^^^^^^^^^^^^^^^^^^^^^^^^^^^^^^\n  File \"/opt/conda/envs/backend-api/lib/python3.12/site-packages/hummingbot/strategy_v2/backtesting/backtesting_engine_base.py\", line 125, in simulate_execution\n    processed_features = self.prepare_market_data()\n                         ^^^^^^^^^^^^^^^^^^^^^^^^^^\n  File \"/opt/conda/envs/backend-api/lib/python3.12/site-packages/hummingbot/strategy_v2/backtesting/backtesting_engine_base.py\", line 178, in prepare_market_data\n    trading_pair=self.controller.config.trading_pair,\n                 ^^^^^^^^^^^^^^^^^^^^^^^^^^^^^^^^^^^\n  File \"/opt/conda/envs/backend-api/lib/python3.12/site-packages/pydantic/main.py\", line 991, in __getattr__\n    raise AttributeError(f'{type(self).__name__!r} object has no attribute {item!r}')\nAttributeError: 'XEMMMultipleLevelsConfig' object has no attribute 'trading_pair'\n"
  ]
}