{
  "error": "An exception occurred during backtesting: 'data'",
  "traceback": [
    "Traceback (most recent call last):\n  File \"/backend-api/routers/manage_backtesting.py\", line 65, in run_backtesting\n    backtesting_results = await backtesting_engine.run_backtesting(\n                          ^^^^^^^^^^^^^^^^^^^^^^^^^^^^^^^^^^^^^^^^^\n  File \"/opt/conda/envs/backend-api/lib/python3.12/site-packages/hummingbot/strategy_v2/backtesting/backtesting_engine_base.py\", line 95, in run_backtesting\n    await self.initialize_backtesting_data_provider()\n  File \"/opt/conda/envs/backend-api/lib/python3.12/site-packages/hummingbot/strategy_v2/backtesting/backtesting_engine_base.py\", line 111, in initialize_backtesting_data_provider\n    await self.controller.market_data_provider.initialize_candles_feed(backtesting_config)\n  File \"/opt/conda/envs/backend-api/lib/python3.12/site-packages/hummingbot/strategy_v2/backtesting/backtesting_data_provider.py\", line 80, in initialize_candles_feed\n    await self.get_candles_feed(config)\n  File \"/opt/conda/envs/backend-api/lib/python3.12/site-packages/hummingbot/strategy_v2/backtesting/backtesting_data_provider.py\", line 106, in get_candles_feed\n    candles_df = await candle_feed.get_historical_candles(config=HistoricalCandlesConfig(\n                 ^^^^^^^^^^^^^^^^^^^^^^^^^^^^^^^^^^^^^^^^^^^^^^^^^^^^^^^^^^^^^^^^^^^^^^^^\n  File \"/opt/conda/envs/backend-api/lib/python3.12/site-packages/hummingbot/data_feed/candles_feed/candles_base.py\", line 193, in get_historical_candles\n    raise e\n  File \"/opt/conda/envs/backend-api/lib/python3.12/site-packages/hummingbot/data_feed/candles_feed/candles_base.py\", line 172, in get_historical_candles\n    candles = await self.fetch_candles(start_time=current_start_time,\n              ^^^^^^^^^^^^^^^^^^^^^^^^^^^^^^^^^^^^^^^^^^^^^^^^^^^^^^^\n  File \"/opt/conda/envs/backend-api/lib/python3.12/site-packages/hummingbot/data_feed/candles_feed/candles_base.py\", line 264, in fetch_candles\n    arr = self._parse_rest_candles(candles, end_time)\n          ^^^^^^^^^^^^^^^^^^^^^^^^^^^^^^^^^^^^^^^^^^^\n  File \"/opt/conda/envs/backend-api/lib/python3.12/site-packages/hummingbot/data_feed/candles_feed/kucoin_spot_candles/kucoin_spot_candles.py\", line 116, in _parse_rest_candles\n    for row in data['data']][::-1]\n               ~~~~^^^^^^^^\nKeyError: 'data'\n"
  ]
}