{
  "error": "An exception occurred during backtesting: No active exception to reraise",
  "traceback": [
    "Traceback (most recent call last):\n  File \"/backend-api/routers/manage_backtesting.py\", line 89, in run_backtesting\n    backtesting_results = await backtesting_engine.run_backtesting(\n                          ^^^^^^^^^^^^^^^^^^^^^^^^^^^^^^^^^^^^^^^^^\n  File \"/opt/conda/envs/backend-api/lib/python3.12/site-packages/hummingbot/strategy_v2/backtesting/backtesting_engine_base.py\", line 95, in run_backtesting\n    await self.initialize_backtesting_data_provider()\n  File \"/opt/conda/envs/backend-api/lib/python3.12/site-packages/hummingbot/strategy_v2/backtesting/backtesting_engine_base.py\", line 111, in initialize_backtesting_data_provider\n    await self.controller.market_data_provider.initialize_candles_feed(backtesting_config)\n  File \"/opt/conda/envs/backend-api/lib/python3.12/site-packages/hummingbot/strategy_v2/backtesting/backtesting_data_provider.py\", line 80, in initialize_candles_feed\n    await self.get_candles_feed(config)\n  File \"/opt/conda/envs/backend-api/lib/python3.12/site-packages/hummingbot/strategy_v2/backtesting/backtesting_data_provider.py\", line 104, in get_candles_feed\n    candle_feed = CandlesFactory.get_candle(config)\n                  ^^^^^^^^^^^^^^^^^^^^^^^^^^^^^^^^^\n  File \"/opt/conda/envs/backend-api/lib/python3.12/site-packages/hummingbot/data_feed/candles_feed/candles_factory.py\", line 76, in get_candle\n    return connector_class(\n           ^^^^^^^^^^^^^^^^\n  File \"/opt/conda/envs/backend-api/lib/python3.12/site-packages/hummingbot/data_feed/candles_feed/mexc_spot_candles/mexc_spot_candles.py\", line 20, in __init__\n    super().__init__(trading_pair, interval, max_records)\n  File \"/opt/conda/envs/backend-api/lib/python3.12/site-packages/hummingbot/data_feed/candles_feed/candles_base.py\", line 65, in __init__\n    raise\nRuntimeError: No active exception to reraise\n"
  ]
}